<?xml version="1.0" encoding="utf-8"?>
<!-- This URDF was automatically created by SolidWorks to URDF Exporter! Originally created by Stephen Brawner (brawner@gmail.com) 
     Commit Version: 1.5.1-0-g916b5db  Build Version: 1.5.7152.31018
     For more information, please see http://wiki.ros.org/sw_urdf_exporter -->
<robot
  name="myturtlebot">

  <link name = "base_footprint"/>

  <link
    name="base_link">
    <inertial>
      <origin
        xyz="0.00010179 4.4427E-07 0.17754"
        rpy="0 0 0" />
      <mass
        value="1.8719" />
      <inertia
        ixx="0.027107"
        ixy="1.9882E-05"
        ixz="-4.0186E-05"
        iyy="0.029311"
        iyz="1.0584E-07"
        izz="0.014323" />
    </inertial>
    <visual>
      <origin
        xyz="0 0 0"
        rpy="0 0 0" />
      <geometry>
        <mesh
          filename="package://myturtlebot/meshes/BODY.STL" />
      </geometry>
      <material
        name="">
        <color
          rgba="0.79216 0.81961 0.93333 1" />
      </material>
    </visual>
    <collision>
      <origin
        xyz="0 0 0"
        rpy="0 0 0" />
      <geometry>
        <mesh
          filename="package://myturtlebot/meshes/BODY.STL" />
      </geometry>
    </collision>
  </link>

  <joint name="base_joint" type="fixed">
    <parent link="base_footprint"/>
    <child link="base_link" />
    <origin xyz="0 0 0.010" rpy="0 0 0"/>
  </joint>

  <link
    name="WHEEL_LEFT">
    <inertial>
      <origin
        xyz="4.1816E-06 0.017628 3.245E-06"
        rpy="0 0 0" />
      <mass
        value="0.080678" />
      <inertia
        ixx="7.9011E-05"
        ixy="-2.3383E-09"
        ixz="-4.9468E-13"
        iyy="0.00013665"
        iyz="-1.8429E-09"
        izz="7.9011E-05" />
    </inertial>
    <visual>
      <origin
        xyz="0 0 0"
        rpy="3.14 0 0" />
      <geometry>
        <mesh
          filename="package://myturtlebot/meshes/WHEEL_LEFT.STL" />
      </geometry>
      <material
        name="">
        <color
          rgba="0.29804 0.29804 0.29804 1" />
      </material>
    </visual>
    <collision>
      <origin
        xyz="0 0 0"
        rpy="0 0 0" />
      <geometry>
        <mesh
          filename="package://myturtlebot/meshes/WHEEL_LEFT.STL" />
      </geometry>
    </collision>
  </link>
  <joint
    name="LF"
    type="continuous">
    <origin
      xyz="-0.000999999999953277 0.0780283661906237 0.0512700000000056"
      rpy="3.14159265358979 -1.5707963267949 0" />
    <parent
      link="base_link" />
    <child
      link="WHEEL_LEFT" />
    <axis
      xyz="0 -1 0" />
  </joint>
  <link
    name="WHEEL_RIGHT">
    <inertial>
      <origin
        xyz="-2.4803E-06 0.017628 -4.681E-06"
        rpy="0 0 0" />
      <mass
        value="0.080678" />
      <inertia
        ixx="7.9011E-05"
        ixy="1.3785E-09"
        ixz="2.9384E-13"
        iyy="0.00013665"
        iyz="2.6394E-09"
        izz="7.9011E-05" />
    </inertial>
    <visual>
      <origin
        xyz="0 0 0"
        rpy="3.14 0 0" />
      <geometry>
        <mesh
          filename="package://myturtlebot/meshes/WHEEL_RIGHT.STL" />
      </geometry>
      <material
        name="">
        <color
          rgba="0.29804 0.29804 0.29804 1" />
      </material>
    </visual>
    <collision>
      <origin
        xyz="0 0 0"
        rpy="0 0 0" />
      <geometry>
        <mesh
          filename="package://myturtlebot/meshes/WHEEL_RIGHT.STL" />
      </geometry>
    </collision>
  </link>
  <joint
    name="RT"
    type="continuous">
    <origin
      xyz="-0.000999999999972886 -0.0780283661906632 0.051270000000006"
      rpy="0 -1.5707963267949 0" />
    <parent
      link="base_link" />
    <child
      link="WHEEL_RIGHT" />
    <axis
      xyz="0 1 0" />
  </joint>
  <link
    name="CASTER_FRONT_CASE">
    <inertial>
      <origin
        xyz="-7.7243E-08 0.0093818 4.9993E-06"
        rpy="0 0 0" />
      <mass
        value="0.022297" />
      <inertia
        ixx="4.2317E-06"
        ixy="-5.2431E-13"
        ixz="-6.6174E-23"
        iyy="6.0233E-06"
        iyz="-8.6692E-23"
        izz="3.9151E-06" />
    </inertial>
    <visual>
      <origin
        xyz="0 0 0"
        rpy="0 0 0" />
      <geometry>
        <mesh
          filename="package://myturtlebot/meshes/CASTER_FRONT_CASE.STL" />
      </geometry>
      <material
        name="">
        <color
          rgba="0.79216 0.81961 0.93333 1" />
      </material>
    </visual>
    <collision>
      <origin
        xyz="0 0 0"
        rpy="0 0 0" />
      <geometry>
        <mesh
          filename="package://myturtlebot/meshes/CASTER_FRONT_CASE.STL" />
      </geometry>
    </collision>
  </link>
  <joint
    name="CFC"
    type="fixed">
    <origin
      xyz="0.08999 -0.001331 0.03"
      rpy="-1.5708 0 -0.030967" />
    <parent
      link="base_link" />
    <child
      link="CASTER_FRONT_CASE" />
    <axis
      xyz="0 0 0" />
  </joint>
  <link
    name="CASTER_FRONT_BALL">
    <inertial>
      <origin
        xyz="-7.3945E-08 -4.9995E-06 2.7756E-17"
        rpy="0 0 0" />
      <mass
        value="0.0081812" />
      <inertia
        ixx="5.1133E-07"
        ixy="-2.4815E-23"
        ixz="1.6456E-23"
        iyy="5.1133E-07"
        iyz="1.8745E-23"
        izz="5.1133E-07" />
    </inertial>
    <visual>
      <origin
        xyz="0 0 0"
        rpy="0 0 0" />
      <geometry>
        <mesh
          filename="package://myturtlebot/meshes/CASTER_FRONT_BALL.STL" />
      </geometry>
      <material
        name="">
        <color
          rgba="0.79216 0.81961 0.93333 1" />
      </material>
    </visual>
    <collision>
      <origin
        xyz="0 0 0"
        rpy="0 0 0" />
      <geometry>
        <mesh
          filename="package://myturtlebot/meshes/CASTER_FRONT_BALL.STL" />
      </geometry>
    </collision>
  </link>
  <joint
    name="CFB"
    type="continuous">
    <origin
      xyz="0 0.0175 0"
      rpy="-1.5708 0.030967 -3.1416" />
    <parent
      link="CASTER_FRONT_CASE" />
    <child
      link="CASTER_FRONT_BALL" />
    <axis
      xyz="1 1 1" />
  </joint>
  <link
    name="CASTER_BACK_CASE">
    <inertial>
      <origin
        xyz="-7.7243E-08 0.0093818 -4.9993E-06"
        rpy="0 0 0" />
      <mass
        value="0.022297" />
      <inertia
        ixx="4.2317E-06"
        ixy="-5.2431E-13"
        ixz="4.8969E-22"
        iyy="6.0233E-06"
        iyz="9.1589E-23"
        izz="3.9151E-06" />
    </inertial>
    <visual>
      <origin
        xyz="0 0 0"
        rpy="0 0 0" />
      <geometry>
        <mesh
          filename="package://myturtlebot/meshes/CASTER_BACK_CASE.STL" />
      </geometry>
      <material
        name="">
        <color
          rgba="0.79216 0.81961 0.93333 1" />
      </material>
    </visual>
    <collision>
      <origin
        xyz="0 0 0"
        rpy="0 0 0" />
      <geometry>
        <mesh
          filename="package://myturtlebot/meshes/CASTER_BACK_CASE.STL" />
      </geometry>
    </collision>
  </link>
  <joint
    name="CBC"
    type="fixed">
    <origin
      xyz="-0.08999 0.001331 0.03"
      rpy="-1.5708 0 -3.1402" />
    <parent
      link="base_link" />
    <child
      link="CASTER_BACK_CASE" />
    <axis
      xyz="0 0 0" />
  </joint>
  <link
    name="CASTER_BACK_BALL">
    <inertial>
      <origin
        xyz="-7.3945E-08 -4.9995E-06 0"
        rpy="0 0 0" />
      <mass
        value="0.0081812" />
      <inertia
        ixx="5.1133E-07"
        ixy="-6.6174E-24"
        ixz="-8.1841E-24"
        iyy="5.1133E-07"
        iyz="3.0769E-23"
        izz="5.1133E-07" />
    </inertial>
    <visual>
      <origin
        xyz="0 0 0"
        rpy="0 0 0" />
      <geometry>
        <mesh
          filename="package://myturtlebot/meshes/CASTER_BACK_BALL.STL" />
      </geometry>
      <material
        name="">
        <color
          rgba="0.79216 0.81961 0.93333 1" />
      </material>
    </visual>
    <collision>
      <origin
        xyz="0 0 0"
        rpy="0 0 0" />
      <geometry>
        <mesh
          filename="package://myturtlebot/meshes/CASTER_BACK_BALL.STL" />
      </geometry>
    </collision>
  </link>
  <joint
    name="CBB"
    type="continuous">
    <origin
      xyz="0 0.0175 0"
      rpy="1.5708 0.001388 0" />
    <parent
      link="CASTER_BACK_CASE" />
    <child
      link="CASTER_BACK_BALL" />
    <axis
      xyz="1 1 1" />
  </joint>
  <link
    name="PI_CAMERA">
    <inertial>
      <origin
        xyz="-0.024074 7.017E-06 -3.5645E-05"
        rpy="0 0 0" />
      <mass
        value="0.025882" />
      <inertia
        ixx="2.6639E-06"
        ixy="-1.0075E-09"
        ixz="-1.8884E-08"
        iyy="5.5839E-06"
        iyz="-8.6051E-10"
        izz="5.5705E-06" />
    </inertial>
    <visual>
      <origin
        xyz="0 0 0"
        rpy="0 0 0" />
      <geometry>
        <mesh
          filename="package://myturtlebot/meshes/PI_CAMERA.STL" />
      </geometry>
      <material
        name="">
        <color
          rgba="0.79216 0.81961 0.93333 1" />
      </material>
    </visual>
    <collision>
      <origin
        xyz="0 0 0"
        rpy="0 0 0" />
      <geometry>
        <mesh
          filename="package://myturtlebot/meshes/PI_CAMERA.STL" />
      </geometry>
    </collision>
  </link>
  <joint
    name="PI_CAM"
    type="fixed">
    <origin
      xyz="0.15313852393051 6.18966041559654E-05 0.297322039651847"
      rpy="0 0.174532925199498 0" />
    <parent
      link="base_link" />
    <child
      link="PI_CAMERA" />
    <axis
      xyz="0 0 0" />
  </joint>
  <link
    name="RASPBERRY_PI">
    <inertial>
      <origin
        xyz="0.012991 0.0023637 0.0073701"
        rpy="0 0 0" />
      <mass
        value="0.017178" />
      <inertia
        ixx="5.1363E-06"
        ixy="6.9056E-08"
        ixz="-1.0943E-06"
        iyy="1.0804E-05"
        iyz="1.797E-08"
        izz="1.5157E-05" />
    </inertial>
    <visual>
      <origin
        xyz="0 0 0"
        rpy="0 0 0" />
      <geometry>
        <mesh
          filename="package://myturtlebot/meshes/RASPBERRY_PI.STL" />
      </geometry>
      <material
        name="">
        <color
          rgba="0.79216 0.81961 0.93333 1" />
      </material>
    </visual>
    <collision>
      <origin
        xyz="0 0 0"
        rpy="0 0 0" />
      <geometry>
        <mesh
          filename="package://myturtlebot/meshes/RASPBERRY_PI.STL" />
      </geometry>
    </collision>
  </link>
  <joint
    name="RPI"
    type="fixed">
    <origin
      xyz="0 0 0.20227"
      rpy="0 0 0.075236" />
    <parent
      link="base_link" />
    <child
      link="RASPBERRY_PI" />
    <axis
      xyz="0 0 0" />
  </joint>
  <link
    name="lidar_link">
    <inertial>
      <origin
        xyz="0.00010179 4.4427E-07 0.17754"
        rpy="0 0 0" />
      <mass
        value="1.8719" />
      <inertia
        ixx="0.027107"
        ixy="1.9882E-05"
        ixz="-4.0186E-05"
        iyy="0.029311"
        iyz="1.0584E-07"
        izz="0.014323" />
    </inertial>
    <visual>
      <origin
        xyz="0 0 0"
        rpy="0 0 0" />
      <geometry>
        <mesh
          filename="package://myturtlebot/meshes/lidar_link.STL" />
      </geometry>
      <material
        name="">
        <color
          rgba="0.79216 0.81961 0.93333 1" />
      </material>
    </visual>
    <collision>
      <origin
        xyz="0 0 0"
        rpy="0 0 0" />
      <geometry>
        <mesh
          filename="package://myturtlebot/meshes/lidar_link.STL" />
      </geometry>
    </collision>
  </link>
  <joint
    name="lidar_joint"
    type="fixed">
    <origin
      xyz="0 0 0.35927"
      rpy="0 0 -0.01479" />
    <parent
      link="base_link" />
    <child
      link="lidar_link" />
    <axis
      xyz="0 0 0" />
  </joint>

  <gazebo reference="lidar_link">
    <sensor type="ray" name="head_hokuyo_sensor">
      <pose>0 0 0 0 0 0</pose>
      <visualize>false</visualize>
      <update_rate>40</update_rate>
      <ray>
        <scan>
          <horizontal>
            <samples>720</samples>
            <resolution>1</resolution>
            <min_angle>-1.57</min_angle>
            <max_angle>1.57</max_angle>
          </horizontal>
        </scan>
        <range>
          <min>0.10</min>
          <max>4.0</max>
          <resolution>0.01</resolution>
        </range>
        <noise>
          <type>gaussian</type>
          <!-- Noise parameters based on published spec for Hokuyo laser
               achieving "+-30mm" accuracy at range < 10m.  A mean of 0.0m and
               stddev of 0.01m will put 99.7% of samples within 0.03m of the true
               reading. -->
          <mean>0.0</mean>
          <stddev>0.01</stddev>
        </noise>
      </ray>
      <plugin name="gazebo_ros_head_hokuyo_controller" filename="libgazebo_ros_laser.so">
        <topicName>scan</topicName>
        <frameName>lidar_link</frameName>
      </plugin>
    </sensor>
  </gazebo>

  <gazebo reference="PI_CAMERA">
    <sensor type="camera" name="rpi_camera">
      <update_rate>30.0</update_rate>
      <camera name="head">
        <horizontal_fov>1.3962634</horizontal_fov>
        <image>
          <width>800</width>
          <height>800</height>
          <format>R8G8B8</format>
        </image>
        <clip>
          <near>0.02</near>
          <far>300</far>
        </clip>
        <noise>
          <type>gaussian</type>
          <!-- Noise is sampled independently per pixel on each frame.
               That pixel's noise value is added to each of its color
               channels, which at that point lie in the range [0,1]. -->
          <mean>0.0</mean>
          <stddev>0.007</stddev>
        </noise>
      </camera>
      <plugin name="camera_controller" filename="libgazebo_ros_camera.so">
        <alwaysOn>true</alwaysOn>
        <updateRate>0.0</updateRate>
        <cameraName>rpi_camera</cameraName>
        <imageTopicName>image_raw</imageTopicName>
        <cameraInfoTopicName>camera_info</cameraInfoTopicName>
        <frameName>PI_CAMERA</frameName>
        <hackBaseline>0.07</hackBaseline>
        <distortionK1>0.0</distortionK1>
        <distortionK2>0.0</distortionK2>
        <distortionK3>0.0</distortionK3>
        <distortionT1>0.0</distortionT1>
        <distortionT2>0.0</distortionT2>
      </plugin>
    </sensor>
  </gazebo>

  <gazebo>
        <plugin name="gazebo_ros_control" filename="libgazebo_ros_control.so">
          <robotNamespace>/myturtlebot</robotNamespace>
          <robotSimType>gazebo_ros_control/DefaultRobotHWSim</robotSimType>
          <legacyModeNS>true</legacyModeNS>
        </plugin>
  </gazebo>

<gazebo>
    <plugin name="differential_drive_controller" filename="libgazebo_ros_diff_drive.so">
      <commandTopic>myturtlebot/cmd_vel</commandTopic>
      <odometryTopic>odom</odometryTopic>
      <odometryFrame>odom</odometryFrame>
      <odometrySource>world</odometrySource>
      <publishOdomTF>true</publishOdomTF>
      <robotBaseFrame>base_footprint</robotBaseFrame>
      <broadcastTF>1</broadcastTF>
      <publishWheelTF>false</publishWheelTF>
      <publishTf>true</publishTf>
      <publishWheelJointState>true</publishWheelJointState>
      <legacyMode>false</legacyMode>
      <updateRate>30</updateRate>
      <leftJoint>LF</leftJoint>
      <rightJoint>RT</rightJoint>
      <wheelSeparation>0.156</wheelSeparation>
      <wheelDiameter>0.100</wheelDiameter>
      <wheelAcceleration>1</wheelAcceleration>
      <wheelTorque>500</wheelTorque>
      <rosDebugLevel>na</rosDebugLevel>
    </plugin>
  </gazebo>

<gazebo reference="base_link">
  <material>Gazebo/Grey</material>
</gazebo>
<gazebo reference="WHEEL_LEFT">
  <material>Gazebo/DarkGrey</material>
</gazebo>
<gazebo reference="WHEEL_RIGHT">
  <material>Gazebo/DarkGrey</material>
</gazebo>
<gazebo reference="CASTER_FRONT_CASE">
  <material>Gazebo/Grey</material>
</gazebo>
<gazebo reference="CASTER_BACK_CASE">
  <material>Gazebo/Grey</material>
</gazebo>
<gazebo reference="CASTER_BACK_BALL">
  <mu1>0.0</mu1>
  <mu2>0.0</mu2>
  <material>Gazebo/Orange</material>
</gazebo>
<gazebo reference="CASTER_FRONT_BALL">
  <mu1>0.0</mu1>
  <mu2>0.0</mu2>
  <material>Gazebo/Orange</material>
</gazebo>
<gazebo reference="lidar_link">
    <material>Gazebo/Blue</material>
</gazebo>
<gazebo reference="RASPBERRY_PI">
    <material>Gazebo/Green</material>
</gazebo>
<!-- <gazebo reference="PI_CAMERA">
    <material>Gazebo/Red</material>
</gazebo> -->

</robot>